Workbook
Name Slicer_Application_Status: #N/A
Name Slicer_Department: #N/A
Name Slicer_Education_Level: #N/A

Sheet Row Data
A1: Applicant_ID | B1: Application_Date | C1: Department | D1: Experience_Years | E1: Education_Level | F1: Interview_Score | G1: Application_Status
A2: APP00216 | B2: 45990 | C2: Sales | D2: 7 | E2: Diploma | F2: 81.5 | G2: Hired
B3: 45927 | C3: IT | D3: 14 | E3: Master | F3: 81.3 | G3: Hired
A4: APP00161 | B4: 45892 | D4: 10 | E4: Bachelor | F4: 90.9 | G4: Hired
A5: APP00280 | B5: 46204 | C5: HR | D5: 15 | E5: Bachelor | F5: 74.7 | G5: Shortlisted
A6: APP00032 | B6: 46154 | C6: Administration | D6: 7 | E6: Master | F6: 83.5 | G6: Hired
A7: APP00124 | B7: 45757 | C7: Finance | D7: 1 | F7: 57 | G7: Shortlisted
A8: APP00228 | B8: 46191 | C8: Sales | D8: 8 | E8: Bachelor | F8: 86 | G8: Hired
A9: APP00069 | B9: 45910 | C9: Operations | D9: 14 | E9: Bachelor | F9: 63.9 | G9: Pending
A10: APP00287 | B10: 45667 | C10: IT | D10: 3 | E10: Bachelor | F10: 75.8 | G10: Rejected
A11: APP00020 | B11: 46012 | C11: Finance | D11: 1 | E11: Master | F11: 89.1
A12: APP00254 | B12: 45883 | C12: HR | D12: 8 | E12: Master | F12: 63.1 | G12: Rejected
A13: APP00080 | B13: 46019 | D13: 4 | E13: Master | F13: 92.4 | G13: Hired
A14: APP00078 | B14: 45890 | C14: Finance | D14: 12 | E14: Bachelor | F14: 88.5 | G14: Hired
A15: APP00238 | B15: 45663 | C15: Operations | D15: 6 | F15: 92.9 | G15: Hired
A16: APP00259 | B16: 45827 | C16: Administration | D16: 5 | E16: Diploma | F16: 98.8 | G16: Hired
A17: APP00187 | B17: 45743 | C17: Administration | D17: 2 | E17: Bachelor | F17: 76.4 | G17: Shortlisted
A18: APP00026 | B18: Unknown | C18: finance | D18: 13 | E18: Bachelor | F18: 74.5 | G18: Rejected
A19: APP00225 | B19: 45981 | C19: Finance | D19: 3 | E19: Diploma | F19: 65.9 | G19: Rejected
A20: APP00165 | B20: 45703 | C20: IT | D20: 2 | E20: Master | F20: 74.4 | G20: Shortlisted
A21: APP00231 | B21: 46190 | C21: IT | D21: 8 | F21: 88.9 | G21: Hired
A22: APP00217 | B22: 46181 | C22: Administration | E22: Bachelor | F22: 97 | G22: Hired
A23: APP00006 | B23: 46197 | C23: Operations | D23: 11 | E23: Bachelor | F23: 74.6 | G23: Shortlisted
A24: APP00227 | B24: 46001 | C24: Sales | D24: 10 | E24: Bachelor | F24: 57.1 | G24: Shortlisted
A25: APP00269 | B25: 46133 | C25: Sales | D25: 12 | E25: PhD | F25: 87.3 | G25: Hired
A26: APP00257 | B26: 46212 | D26: 7 | E26: Bachelor | F26: 61.5 | G26: Rejected
A27: APP00194 | B27: 46207 | C27: Administration | D27: 11 | E27: Master | G27: Hired
A28: APP00039 | B28: 45901 | C28: Administration | E28: Bachelor | F28: 80.2 | G28: Hired
A29: APP00159 | B29: 45736 | C29: Sales | D29: 12 | E29: Diploma | G29: Hired
A30: APP00141 | B30: 46090 | D30: 11 | E30: Master | F30: 73.7 | G30: Rejected
A31: APP00129 | B31: 45819 | C31: HR | D31: 7 | E31: Bachelor | F31: 71.9 | G31: Pending
A32: APP00247 | B32: 46020 | C32: Administration | D32: 4 | E32: Bachelor | F32: 48.1 | G32: Shortlisted
B33: 45898 | C33: Administration | D33: 0 | E33: bachelor | F33: 59.6 | G33: Shortlisted
A34: APP00267 | B34: 45807 | C34: Sales | D34: 9 | E34: Master | F34: 71.9 | G34: Pending
A35: APP00163 | C35: Administration | D35: 0 | E35: bachelor | F35: 47 | G35: Rejected
A36: APP00281 | B36: 45692 | C36: Finance | D36: 12 | E36: Bachelor | F36: 91.1 | G36: Hired
A37: APP00224 | B37: 46128 | C37: Sales | D37: 13 | E37: Bachelor | F37: 86.1 | G37: Hired
A38: APP00091 | C38: IT | D38: 13 | E38: Bachelor | F38: 60.4 | G38: NULL
A39: APP00047 | B39: 45958 | C39: HR | D39: 11 | E39: Master | F39: 79.4 | G39: Rejected
A40: APP00009 | B40: 45913 | C40: IT | D40: 1 | E40: Bachelor | F40: 61.6 | G40: Shortlisted
...

Sheet Clean Data
A1: Applicant_ID | B1: Application_Date | C1: Department | D1: Experience_Years | E1: Education_Level | F1: Interview_Score | G1: Application_Status | H1: Interview Performance | I1: Application Year | J1: Application Month | K1: Application Day
A2: APP00288 | B2: 46234 | C2: Operations | D2: 9 | E2: Bachelor | F2: 89.3 | G2: Hired | H2: =IF(F2>=70,"Pass","Fail") -> Pass | I2: =YEAR(B2) -> 2026 | J2: =MONTH(B2) -> 7 | K2: =DAY(B2) -> 31
A3: APP00241 | B3: 46231 | C3: IT | D3: 9 | E3: Bachelor | F3: 85.3 | G3: Hired | H3: =IF(F3>=70,"Pass","Fail") -> Pass | I3: =YEAR(B3) -> 2026 | J3: =MONTH(B3) -> 7 | K3: =DAY(B3) -> 28
A4: APP00244 | B4: 46231 | C4: Administration | D4: 13 | E4: Diploma | F4: 79.2 | G4: Shortlisted | H4: =IF(F4>=70,"Pass","Fail") -> Pass | I4: =YEAR(B4) -> 2026 | J4: =MONTH(B4) -> 7 | K4: =DAY(B4) -> 28 | N4: Data Problem Found
A5: APP00219 | B5: 46228 | C5: IT | D5: 4 | E5: Bachelor | F5: 74 | G5: Rejected | H5: =IF(F5>=70,"Pass","Fail") -> Pass | I5: =YEAR(B5) -> 2026 | J5: =MONTH(B5) -> 7 | K5: =DAY(B5) -> 25 | N5: Issue ID | O5: 15 blanks
A6: APP00084 | B6: 46226 | C6: Sales | D6: 1 | E6: Diploma | F6: 46.6 | G6: Pending | H6: =IF(F6>=70,"Pass","Fail") -> Fail | I6: =YEAR(B6) -> 2026 | J6: =MONTH(B6) -> 7 | K6: =DAY(B6) -> 23 | N6: Department | O6: 18 Blanks
A7: APP00148 | B7: 46225 | C7: Finance | D7: 9 | E7: Bachelor | F7: 71.8 | G7: Rejected | H7: =IF(F7>=70,"Pass","Fail") -> Pass | I7: =YEAR(B7) -> 2026 | J7: =MONTH(B7) -> 7 | K7: =DAY(B7) -> 22 | N7: Date | O7: 19 Blanks and -9,_
A8: APP00043 | B8: 46225 | C8: Finance | D8: 6 | E8: Bachelor | F8: 54.7 | G8: Shortlisted | H8: =IF(F8>=70,"Pass","Fail") -> Fail | I8: =YEAR(B8) -> 2026 | J8: =MONTH(B8) -> 7 | K8: =DAY(B8) -> 22 | N8: Experience Years | O8: 25 Blanks ,Null,NA,_,-9
A9: APP00240 | B9: 46222 | C9: Unknown | D9: 9 | E9: Diploma | F9: 97.6 | G9: Hired | H9: =IF(F9>=70,"Pass","Fail") -> Pass | I9: =YEAR(B9) -> 2026 | J9: =MONTH(B9) -> 7 | K9: =DAY(B9) -> 19 | N9: Education Lavel | O9: 19 Blanks
A10: APP00110 | B10: 46222 | C10: Finance | D10: 1 | E10: Diploma | F10: 89.9 | G10: Shortlisted | H10: =IF(F10>=70,"Pass","Fail") -> Pass | I10: =YEAR(B10) -> 2026 | J10: =MONTH(B10) -> 7 | K10: =DAY(B10) -> 19 | N10: Interview Score | O10: 18 Blanks ,119,123,_
A11: APP00205 | B11: 46218 | C11: Sales | D11: 11 | E11: Bachelor | F11: 87.2 | G11: Hired | H11: =IF(F11>=70,"Pass","Fail") -> Pass | I11: =YEAR(B11) -> 2026 | J11: =MONTH(B11) -> 7 | K11: =DAY(B11) -> 15 | N11: Application Status | O11: 18 Blanks,NULL
A12: APP00122 | B12: 46218 | C12: Sales | D12: 8 | E12: Master | F12: 84.1 | G12: Hired | H12: =IF(F12>=70,"Pass","Fail") -> Pass | I12: =YEAR(B12) -> 2026 | J12: =MONTH(B12) -> 7 | K12: =DAY(B12) -> 15 | N12: Total | O12: 132
A13: APP00220 | B13: 46216 | C13: Operations | D13: 6 | E13: Master | F13: 74 | G13: Shortlisted | H13: =IF(F13>=70,"Pass","Fail") -> Pass | I13: =YEAR(B13) -> 2026 | J13: =MONTH(B13) -> 7 | K13: =DAY(B13) -> 13
A14: APP00284 | B14: 46213 | C14: Sales | D14: 7 | E14: Bachelor | F14: 85.8 | G14: Hired | H14: =IF(F14>=70,"Pass","Fail") -> Pass | I14: =YEAR(B14) -> 2026 | J14: =MONTH(B14) -> 7 | K14: =DAY(B14) -> 10 | N14: Average | O14: =MEDIAN(F47:F339) -> 74
A15: MISSING_ID_004 | B15: 46213 | C15: IT | D15: 6 | E15: Bachelor | F15: 77.4 | G15: Shortlisted | H15: =IF(F15>=70,"Pass","Fail") -> Pass | I15: =YEAR(B15) -> 2026 | J15: =MONTH(B15) -> 7 | K15: =DAY(B15) -> 10
A16: APP00257 | B16: 46212 | C16: Unknown | D16: 7 | E16: Bachelor | F16: 61.5 | G16: Rejected | H16: =IF(F16>=70,"Pass","Fail") -> Fail | I16: =YEAR(B16) -> 2026 | J16: =MONTH(B16) -> 7 | K16: =DAY(B16) -> 9
A17: APP00018 | B17: 46208 | C17: Sales | D17: 2 | E17: Bachelor | F17: 74 | G17: Shortlisted | H17: =IF(F17>=70,"Pass","Fail") -> Pass | I17: =YEAR(B17) -> 2026 | J17: =MONTH(B17) -> 7 | K17: =DAY(B17) -> 5
A18: APP00194 | B18: 46207 | C18: Administration | D18: 11 | E18: Master | F18: 74 | G18: Hired | H18: =IF(F18>=70,"Pass","Fail") -> Pass | I18: =YEAR(B18) -> 2026 | J18: =MONTH(B18) -> 7 | K18: =DAY(B18) -> 4
A19: APP00178 | B19: 46205 | C19: Operations | D19: 6 | E19: Master | F19: 58.3 | G19: Rejected | H19: =IF(F19>=70,"Pass","Fail") -> Fail | I19: =YEAR(B19) -> 2026 | J19: =MONTH(B19) -> 7 | K19: =DAY(B19) -> 2
A20: APP00280 | B20: 46204 | C20: HR | D20: 15 | E20: Bachelor | F20: 74.7 | G20: Shortlisted | H20: =IF(F20>=70,"Pass","Fail") -> Pass | I20: =YEAR(B20) -> 2026 | J20: =MONTH(B20) -> 7 | K20: =DAY(B20) -> 1
A21: MISSING_ID_005 | B21: 46202 | C21: IT | D21: 13 | E21: Diploma | F21: 69.3 | G21: Shortlisted | H21: =IF(F21>=70,"Pass","Fail") -> Fail | I21: =YEAR(B21) -> 2026 | J21: =MONTH(B21) -> 6 | K21: =DAY(B21) -> 29
A22: APP00169 | B22: 46200 | C22: Sales | D22: 5 | E22: Master | F22: 46.6 | G22: Shortlisted | H22: =IF(F22>=70,"Pass","Fail") -> Fail | I22: =YEAR(B22) -> 2026 | J22: =MONTH(B22) -> 6 | K22: =DAY(B22) -> 27
A23: APP00213 | B23: 46198 | C23: HR | D23: 7 | E23: Bachelor | F23: 79.3 | G23: Shortlisted | H23: =IF(F23>=70,"Pass","Fail") -> Pass | I23: =YEAR(B23) -> 2026 | J23: =MONTH(B23) -> 6 | K23: =DAY(B23) -> 25
A24: APP00275 | B24: 46197 | C24: Administration | D24: 8 | E24: Unknown | F24: 91.3 | G24: Hired | H24: =IF(F24>=70,"Pass","Fail") -> Pass | I24: =YEAR(B24) -> 2026 | J24: =MONTH(B24) -> 6 | K24: =DAY(B24) -> 24
A25: APP00006 | B25: 46197 | C25: Operations | D25: 11 | E25: Bachelor | F25: 74.6 | G25: Shortlisted | H25: =IF(F25>=70,"Pass","Fail") -> Pass | I25: =YEAR(B25) -> 2026 | J25: =MONTH(B25) -> 6 | K25: =DAY(B25) -> 24
A26: APP00065 | B26: 46197 | C26: Operations | D26: 5 | E26: Diploma | F26: 62.1 | G26: Pending | H26: =IF(F26>=70,"Pass","Fail") -> Fail | I26: =YEAR(B26) -> 2026 | J26: =MONTH(B26) -> 6 | K26: =DAY(B26) -> 24
... A177: APP00002 | B177: 45895 | C177: Unknown | D177: 10 | E177: Bachelor | F177: 73.1 | G177: Pending | H177: =IF(F177>=70,"Pass","Fail") -> Pass | I177: =YEAR(B177) -> 2025 | J177: =MONTH(B177) -> 8 | K177: =DAY(B177) -> 26
A178: APP00161 | B178: 45892 | C178: Sales | D178: 10 | E178: Bachelor | F178: 90.9 | G178: Hired | H178: =IF(F178>=70,"Pass","Fail") -> Pass | I178: =YEAR(B178) -> 2025 | J178: =MONTH(B178) -> 8 | K178: =DAY(B178) -> 23 | L178: =MEDIAN(D176:D468) -> 7
A179: APP00226 | B179: 45892 | C179: HR | D179: 14 | E179: Bachelor | F179: 84.2 | G179: Hired | H179: =IF(F179>=70,"Pass","Fail") -> Pass | I179: =YEAR(B179) -> 2025 | J179: =MONTH(B179) -> 8 | K179: =DAY(B179) -> 23
A180: APP00128 | B180: 45892 | C180: Finance | D180: 13 | E180: Bachelor | F180: 41.7 | G180: Pending | H180: =IF(F180>=70,"Pass","Fail") -> Fail | I180: =YEAR(B180) -> 2025 | J180: =MONTH(B180) -> 8 | K180: =DAY(B180) -> 23
A181: APP00078 | B181: 45890 | C181: Finance | D181: 12 | E181: Bachelor | F181: 88.5 | G181: Hired | H181: =IF(F181>=70,"Pass","Fail") -> Pass | I181: =YEAR(B181) -> 2025 | J181: =MONTH(B181) -> 8 | K181: =DAY(B181) -> 21
A182: APP00041 | B182: 45890 | C182: IT | D182: 3 | E182: Master | F182: 58.8 | G182: Shortlisted | H182: =IF(F182>=70,"Pass","Fail") -> Fail | I182: =YEAR(B182) -> 2025 | J182: =MONTH(B182) -> 8 | K182: =DAY(B182) -> 21
A183: APP00094 | B183: 45889 | C183: Sales | D183: 10 | E183: Unknown | F183: 73.7 | G183: Rejected | H183: =IF(F183>=70,"Pass","Fail") -> Pass | I183: =YEAR(B183) -> 2025 | J183: =MONTH(B183) -> 8 | K183: =DAY(B183) -> 20
A184: APP00133 | B184: 45887 | C184: Operations | D184: 13 | E184: Bachelor | F184: 74 | G184: Pending | H184: =IF(F184>=70,"Pass","Fail") -> Pass | I184: =YEAR(B184) -> 2025 | J184: =MONTH(B184) -> 8 | K184: =DAY(B184) -> 18
A185: APP00137 | B185: 45886 | C185: Sales | D185: 7 | E185: Master | F185: 89.5 | G185: Hired | H185: =IF(F185>=70,"Pass","Fail") -> Pass | I185: =YEAR(B185) -> 2025 | J185: =MONTH(B185) -> 8 | K185: =DAY(B185) -> 17
A186: APP00024 | B186: 45885 | C186: Unknown | D186: 15 | E186: Master | F186: 78 | G186: Rejected | H186: =IF(F186>=70,"Pass","Fail") -> Pass | I186: =YEAR(B186) -> 2025 | J186: =MONTH(B186) -> 8 | K186: =DAY(B186) -> 16
A187: APP00262 | B187: 45883 | C187: Finance | D187: 2 | E187: PhD | F187: 74 | G187: Shortlisted | H187: =IF(F187>=70,"Pass","Fail") -> Pass | I187: =YEAR(B187) -> 2025 | J187: =MONTH(B187) -> 8 | K187: =DAY(B187) -> 14
A188: APP00254 | B188: 45883 | C188: HR | D188: 8 | E188: Master | F188: 63.1 | G188: Rejected | H188: =IF(F188>=70,"Pass","Fail") -> Fail | I188: =YEAR(B188) -> 2025 | J188: =MONTH(B188) -> 8 | K188: =DAY(B188) -> 14
A189: APP00111 | B189: 45876 | C189: Finance | D189: 10 | E189: Bachelor | F189: 64.8 | G189: Pending | H189: =IF(F189>=70,"Pass","Fail") -> Fail | I189: =YEAR(B189) -> 2025 | J189: =MONTH(B189) -> 8 | K189: =DAY(B189) -> 7
A190: APP00010 | B190: 45874 | C190: Administration | D190: 12 | E190: Bachelor | F190: 85.3 | G190: Hired | H190: =IF(F190>=70,"Pass","Fail") -> Pass | I190: =YEAR(B190) -> 2025 | J190: =MONTH(B190) -> 8 | K190: =DAY(B190) -> 5
...

Sheet Analysis
A1: Text Cleaning | F1: Basic Calculation
A2: Department Origin | B2: TRIM | C2: Proper | D2: Upper | F2: Total Experance Year | G2: =SUM('Clean Data'!D2:D294) -> 2197
A3: ='Clean Data'!C2 -> Operations | B3: =TRIM(A3) -> Operations | C3: =PROPER(B3) -> Operations | D3: =UPPER('Clean Data'!G2) -> HIRED | F3: Average Interview score | G3: =AVERAGE('Clean Data'!F2:F294) -> 72.919113
A4: ='Clean Data'!C3 -> IT | B4: =TRIM(A4) -> IT | C4: =PROPER(B4) -> It | D4: =UPPER('Clean Data'!G3) -> HIRED | F4: Numer of Inteview Scores | G4: =COUNT('Clean Data'!F2:F294) -> 293
A5: ='Clean Data'!C4 -> Administration | B5: =TRIM(A5) -> Administration | C5: =PROPER(B5) -> Administration | D5: =UPPER('Clean Data'!G4) -> SHORTLISTED | F5: Lowest Interview Score | G5: =MIN('Clean Data'!F2:F294) -> 27.4
A6: ='Clean Data'!C5 -> IT | B6: =TRIM(A6) -> IT | C6: =PROPER(B6) -> It | D6: =UPPER('Clean Data'!G5) -> REJECTED | F6: Highest Interview Score | G6: =MAX('Clean Data'!F2:F294) -> 100
A7: ='Clean Data'!C6 -> Sales | B7: =TRIM(A7) -> Sales | C7: =PROPER(B7) -> Sales | D7: =UPPER('Clean Data'!G6) -> PENDING
A8: ='Clean Data'!C7 -> Finance | B8: =TRIM(A8) -> Finance | C8: =PROPER(B8) -> Finance | D8: =UPPER('Clean Data'!G7) -> REJECTED
A9: ='Clean Data'!C8 -> Finance | B9: =TRIM(A9) -> Finance | C9: =PROPER(B9) -> Finance | D9: =UPPER('Clean Data'!G8) -> SHORTLISTED | F9: Conditional Functions
A10: ='Clean Data'!C9 -> Unknown | B10: =TRIM(A10) -> Unknown | C10: =PROPER(B10) -> Unknown | D10: =UPPER('Clean Data'!G9) -> HIRED | F10: Total Hired Applicants | G10: =COUNTIF('Clean Data'!G2:G294,"Hired") -> 85
A11: ='Clean Data'!C10 -> Finance | B11: =TRIM(A11) -> Finance | C11: =PROPER(B11) -> Finance | D11: =UPPER('Clean Data'!G10) -> SHORTLISTED | F11: Total Rejected Applicants | G11: =COUNTIF('Clean Data'!G2:G294,"Rejected") -> 73
A12: ='Clean Data'!C11 -> Sales | B12: =TRIM(A12) -> Sales | C12: =PROPER(B12) -> Sales | D12: =UPPER('Clean Data'!G11) -> HIRED | F12: Avg Interview Score Hired | G12: =AVERAGEIF('Clean Data'!G2:G294,"Hired",'Clean Data'!F2:F294) -> 87.357647
A13: ='Clean Data'!C12 -> Sales | B13: =TRIM(A13) -> Sales | C13: =PROPER(B13) -> Sales | D13: =UPPER('Clean Data'!G12) -> HIRED | F13: Total Interview Scores of Hired Applicants | G13: =SUMIF('Clean Data'!G2:G294,"Hired",'Clean Data'!F2:F294) -> 7425.4
A14: ='Clean Data'!C13 -> Operations | B14: =TRIM(A14) -> Operations | C14: =PROPER(B14) -> Operations | D14: =UPPER('Clean Data'!G13) -> SHORTLISTED
A15: ='Clean Data'!C14 -> Sales | B15: =TRIM(A15) -> Sales | C15: =PROPER(B15) -> Sales | D15: =UPPER('Clean Data'!G14) -> HIRED
A16: ='Clean Data'!C15 -> IT | B16: =TRIM(A16) -> IT | C16: =PROPER(B16) -> It | D16: =UPPER('Clean Data'!G15) -> SHORTLISTED | F16: kpi 1
A17: ='Clean Data'!C16 -> Unknown | B17: =TRIM(A17) -> Unknown | C17: =PROPER(B17) -> Unknown | D17: =UPPER('Clean Data'!G16) -> REJECTED | E17: 1 | F17: Total applicants | G17: =COUNTA('Clean Data'!A2:A294) -> 293
A18: ='Clean Data'!C17 -> Sales | B18: =TRIM(A18) -> Sales | C18: =PROPER(B18) -> Sales | D18: =UPPER('Clean Data'!G17) -> SHORTLISTED | E18: 2 | F18: Hired Applicants | G18: =COUNTIF('Clean Data'!G2:G294,"Hired") -> 85
A19: ='Clean Data'!C18 -> Administration | B19: =TRIM(A19) -> Administration | C19: =PROPER(B19) -> Administration | D19: =UPPER('Clean Data'!G18) -> HIRED | E19: 3 | F19: Average Experience Year | G19: =AVERAGE('Clean Data'!D2:D294) -> 7.5239726
A20: ='Clean Data'!C19 -> Operations | B20: =TRIM(A20) -> Operations | C20: =PROPER(B20) -> Operations | D20: =UPPER('Clean Data'!G19) -> REJECTED | E20: 4 | F20: Average Interview Score | G20: =AVERAGE('Clean Data'!F2:F294) -> 72.919113
A21: ='Clean Data'!C20 -> HR | B21: =TRIM(A21) -> HR | C21: =PROPER(B21) -> Hr | D21: =UPPER('Clean Data'!G20) -> SHORTLISTED
A22: ='Clean Data'!C21 -> IT | B22: =TRIM(A22) -> IT | C22: =PROPER(B22) -> It | D22: =UPPER('Clean Data'!G21) -> SHORTLISTED
A23: ='Clean Data'!C22 -> Sales | B23: =TRIM(A23) -> Sales | C23: =PROPER(B23) -> Sales | D23: =UPPER('Clean Data'!G22) -> SHORTLISTED
A24: ='Clean Data'!C23 -> HR | B24: =TRIM(A24) -> HR | C24: =PROPER(B24) -> Hr | D24: =UPPER('Clean Data'!G23) -> SHORTLISTED
A25: ='Clean Data'!C24 -> Administration | B25: =TRIM(A25) -> Administration | C25: =PROPER(B25) -> Administration | D25: =UPPER('Clean Data'!G24) -> HIRED
A26: ='Clean Data'!C25 -> Operations | B26: =TRIM(A26) -> Operations | C26: =PROPER(B26) -> Operations | D26: =UPPER('Clean Data'!G25) -> SHORTLISTED
A27: ='Clean Data'!C26 -> Operations | B27: =TRIM(A27) -> Operations | C27: =PROPER(B27) -> Operations | D27: =UPPER('Clean Data'!G26) -> PENDING
A28: ='Clean Data'!C27 -> Administration | B28: =TRIM(A28) -> Administration | C28: =PROPER(B28) -> Administration | D28: =UPPER('Clean Data'!G27) -> REJECTED
A29: ='Clean Data'!C28 -> Finance | B29: =TRIM(A29) -> Finance | C29: =PROPER(B29) -> Finance | D29: =UPPER('Clean Data'!G28) -> REJECTED
A30: ='Clean Data'!C29 -> Sales | B30: =TRIM(A30) -> Sales | C30: =PROPER(B30) -> Sales | D30: =UPPER('Clean Data'!G29) -> HIRED
A31: ='Clean Data'!C30 -> Sales | B31: =TRIM(A31) -> Sales | C31: =PROPER(B31) -> Sales | D31: =UPPER('Clean Data'!G30) -> HIRED
A32: ='Clean Data'!C31 -> IT | B32: =TRIM(A32) -> IT | C32: =PROPER(B32) -> It | D32: =UPPER('Clean Data'!G31) -> HIRED
... A295: ='Clean Data'!C294 -> Unknown | B295: =TRIM(A295) -> Unknown | C295: =PROPER(B295) -> Unknown | D295: =UPPER('Clean Data'!G294) -> SHORTLISTED
C296: =PROPER(B296)

Sheet Pivot Tables
B2: Count of Application_Status | C2: Column Labels
B3: Row Labels | C3: Hired | D3: Pending | E3: Rejected | F3: Shortlisted | G3: Grand Total | H3: 1
B4: HR | C4: 3 | D4: 5 | E4: 7 | F4: 3 | G4: 18
B5: IT | C5: 3 | D5: 2 | E5: 6 | F5: 4 | G5: 15
B6: Grand Total | C6: 6 | D6: 7 | E6: 13 | F6: 7 | G6: 33
I11: 2
C12: 4 | F12: 3
B13: Row Labels | C13: Sum of Interview_Score | E13: Row Labels | F13: Count of Application_Status
B14: HR | C14: 1266.4 | E14: Hired | F14: 6
B15: IT | C15: 1086.4 | E15: Pending | F15: 7
B16: Grand Total | C16: 2352.8 | E16: Rejected | F16: 13
E17: Shortlisted | F17: 7
E18: Grand Total | F18: 33
E20: Row Labels | F20: Average of Experience_Years
E21: HR | F21: 8.1666667
E22: IT | F22: 7.1333333
E23: Grand Total | F23: 7.6969697

Sheet Dashboard
A1: JOB APPLICANT DATA ANALYTICS DASHBOARD
D11: Count of Application_Status | E11: Column Labels
D12: Row Labels | E12: Hired | F12: Pending | G12: Rejected | H12: Shortlisted | I12: Grand Total
D13: HR | E13: 3 | F13: 5 | G13: 7 | H13: 3 | I13: 18
D14: IT | E14: 3 | F14: 2 | G14: 6 | H14: 4 | I14: 15
D15: Grand Total | E15: 6 | F15: 7 | G15: 13 | H15: 7 | I15: 33
D22: Row Labels | E22: Count of Application_Status | H22: Row Labels | I22: Sum of Interview_Score
D23: Hired | E23: 6 | F23: Row Labels | G23: Average of Experience_Years | H23: HR | I23: 1266.4
D24: Pending | E24: 7 | F24: HR | G24: 8.1666667 | H24: IT | I24: 1086.4
D25: Rejected | E25: 13 | F25: IT | G25: 7.1333333 | H25: Grand Total | I25: 2352.8
D26: Shortlisted | E26: 7 | F26: Grand Total | G26: 7.6969697
D27: Grand Total | E27: 33
